Workbook

Sheet Checklist
A1: Checklist
A2: Step 1: fill in the course set-up below when work starts. Step 2: update the status of each item as work progresses. Step 3: check the counts, then the Course Creator confirms the content is ready for upload.
A4: Course title | B4: =IF('Course info'!B5="","",'Course info'!B5) -> Modeling life | E4: From Course info.
A5: Course ID | B5: C001 | E5: Filled in by the Operator after the course is created.
A6: Learning language | B6: English | E6: Languages of the video and text files. Locked once the course is created. Everything else is required in English and Chinese.
A7: Study mode | B7: Both | E7: Video, Text or Both. Locked once the course is created.
A8: Number of lessons | B8: 2 | E8: Used below to check that nothing is missing.
A9: Course Creator | B9: Harry | E9: Name.
A10: Shared folder link
A11: Planned go-live date
A13: # | B13: Deliverable | C13: Owner | D13: Applies | E13: Status | F13: Where | G13: Last updated | H13: Notes
A14: 1 | B14: Course info – English and Chinese | C14: Course Creator | D14: Yes | E14: Not started | F14: Tab: Course info | I14: Yes
A15: 2 | B15: Lesson info and learning point titles – English and Chinese, all lessons | C15: Course Creator | D15: Yes | E15: Not started | F15: Tab: Lessons | I15: Yes
A16: 3 | B16: Course cover | C16: Graphic Designer | D16: Yes | E16: Not started | F16: See shared folder | I16: Yes
A17: 4 | B17: Video files – English, all lessons | C17: Video & Text Manager | D17: Yes | E17: Not started | F17: See shared folder | I17: =IF(AND(OR($B$6="English & Chinese",$B$6="English"),OR($B$7="Both",$B$7="Video")),"Yes","N/A") -> Yes
A18: 5 | B18: Video files – Chinese, all lessons | C18: Video & Text Manager | D18: Yes | E18: Not started | F18: See shared folder | I18: =IF(AND(OR($B$6="English & Chinese",$B$6="Chinese"),OR($B$7="Both",$B$7="Video")),"Yes","N/A") -> N/A
A19: 6 | B19: Video learning point times – English video | C19: Video & Text Manager | D19: Yes | E19: Not started | F19: Tab: Lessons | I19: =IF(AND(OR($B$6="English & Chinese",$B$6="English"),OR($B$7="Both",$B$7="Video")),"Yes","N/A") -> Yes
A20: 7 | B20: Video learning point times – Chinese video | C20: Video & Text Manager | D20: Yes | E20: Not started | F20: Tab: Lessons | I20: =IF(AND(OR($B$6="English & Chinese",$B$6="Chinese"),OR($B$7="Both",$B$7="Video")),"Yes","N/A") -> N/A
A21: 8 | B21: Text files – English, all lessons (learning point titles as Heading 1) | C21: Video & Text Manager | D21: Yes | E21: Not started | F21: See shared folder | I21: =IF(AND(OR($B$6="English & Chinese",$B$6="English"),OR($B$7="Both",$B$7="Text")),"Yes","N/A") -> Yes
A22: 9 | B22: Text files – Chinese, all lessons (learning point titles as Heading 1) | C22: Video & Text Manager | D22: Yes | E22: Not started | F22: See shared folder | I22: =IF(AND(OR($B$6="English & Chinese",$B$6="Chinese"),OR($B$7="Both",$B$7="Text")),"Yes","N/A") -> N/A
A23: 10 | B23: Exhibit files and thumbnails | C23: Graphic Designer | D23: Yes | E23: Not started | F23: See shared folder | I23: Yes
A24: 11 | B24: Exhibit details – English and Chinese, with video trigger times | C24: Course Creator | D24: Yes | E24: Not started | F24: Tab: Exhibits | I24: Yes
A25: 12 | B25: Knowledge test – English and Chinese, all lessons | C25: Course Creator | D25: Yes | E25: Not started | F25: Tab: Knowledge test | I25: Yes
A26: 13 | B26: Application test – English and Chinese, all lessons | C26: Course Creator | D26: Yes | E26: Not started | F26: Tab: Application test | I26: Yes
A27: 14 | B27: Reading list – English, all lessons | C27: Course Creator | D27: Yes | E27: Not started | F27: Tab: Reading list | I27: Yes
B28: Applies turns orange when it does not match the learning language or study mode above.
A30: Content counts – check that nothing is missing
A31: Lessons in the Lessons tab | B31: =COUNTIFS(Lessons!$A:$A,"Lesson title (EN)",Lessons!$B:$B,"<>")&" / "&$B$8 -> 2 / 2
A32: Lesson | B32: Knowledge test questions | C32: Application test | D32: Exhibits | E32: Readings
A33: =IF(1<=$B$8,"Lesson 1","") -> Lesson 1 | B33: =IF($A33="","",COUNTIF('Knowledge test'!$B:$B,$A33)) -> 18 | C33: =IF($A33="","",COUNTIF('Application test'!$B:$B,$A33)) -> 1 | D33: =IF($A33="","",COUNTIF(Exhibits!$B:$B,$A33)) -> 2 | E33: =IF($A33="","",COUNTIF('Reading list'!$B:$B,$A33)) -> 3
A34: =IF(2<=$B$8,"Lesson 2","") -> Lesson 2 | B34: =IF($A34="","",COUNTIF('Knowledge test'!$B:$B,$A34)) -> 8 | C34: =IF($A34="","",COUNTIF('Application test'!$B:$B,$A34)) -> 1 | D34: =IF($A34="","",COUNTIF(Exhibits!$B:$B,$A34)) -> 2 | E34: =IF($A34="","",COUNTIF('Reading list'!$B:$B,$A34)) -> 3
A35: =IF(3<=$B$8,"Lesson 3","") | B35: =IF($A35="","",COUNTIF('Knowledge test'!$B:$B,$A35)) | C35: =IF($A35="","",COUNTIF('Application test'!$B:$B,$A35)) | D35: =IF($A35="","",COUNTIF(Exhibits!$B:$B,$A35)) | E35: =IF($A35="","",COUNTIF('Reading list'!$B:$B,$A35))
A36: =IF(4<=$B$8,"Lesson 4","") | B36: =IF($A36="","",COUNTIF('Knowledge test'!$B:$B,$A36)) | C36: =IF($A36="","",COUNTIF('Application test'!$B:$B,$A36)) | D36: =IF($A36="","",COUNTIF(Exhibits!$B:$B,$A36)) | E36: =IF($A36="","",COUNTIF('Reading list'!$B:$B,$A36))
A37: =IF(5<=$B$8,"Lesson 5","") | B37: =IF($A37="","",COUNTIF('Knowledge test'!$B:$B,$A37)) | C37: =IF($A37="","",COUNTIF('Application test'!$B:$B,$A37)) | D37: =IF($A37="","",COUNTIF(Exhibits!$B:$B,$A37)) | E37: =IF($A37="","",COUNTIF('Reading list'!$B:$B,$A37))
A38: =IF(6<=$B$8,"Lesson 6","") | B38: =IF($A38="","",COUNTIF('Knowledge test'!$B:$B,$A38)) | C38: =IF($A38="","",COUNTIF('Application test'!$B:$B,$A38)) | D38: =IF($A38="","",COUNTIF(Exhibits!$B:$B,$A38)) | E38: =IF($A38="","",COUNTIF('Reading list'!$B:$B,$A38))
A39: =IF(7<=$B$8,"Lesson 7","") | B39: =IF($A39="","",COUNTIF('Knowledge test'!$B:$B,$A39)) | C39: =IF($A39="","",COUNTIF('Application test'!$B:$B,$A39)) | D39: =IF($A39="","",COUNTIF(Exhibits!$B:$B,$A39)) | E39: =IF($A39="","",COUNTIF('Reading list'!$B:$B,$A39))
A40: =IF(8<=$B$8,"Lesson 8","") | B40: =IF($A40="","",COUNTIF('Knowledge test'!$B:$B,$A40)) | C40: =IF($A40="","",COUNTIF('Application test'!$B:$B,$A40)) | D40: =IF($A40="","",COUNTIF(Exhibits!$B:$B,$A40)) | E40: =IF($A40="","",COUNTIF('Reading list'!$B:$B,$A40))
A41: =IF(9<=$B$8,"Lesson 9","") | B41: =IF($A41="","",COUNTIF('Knowledge test'!$B:$B,$A41)) | C41: =IF($A41="","",COUNTIF('Application test'!$B:$B,$A41)) | D41: =IF($A41="","",COUNTIF(Exhibits!$B:$B,$A41)) | E41: =IF($A41="","",COUNTIF('Reading list'!$B:$B,$A41))
A42: =IF(10<=$B$8,"Lesson 10","") | B42: =IF($A42="","",COUNTIF('Knowledge test'!$B:$B,$A42)) | C42: =IF($A42="","",COUNTIF('Application test'!$B:$B,$A42)) | D42: =IF($A42="","",COUNTIF(Exhibits!$B:$B,$A42)) | E42: =IF($A42="","",COUNTIF('Reading list'!$B:$B,$A42))
A43: =IF(11<=$B$8,"Lesson 11","") | B43: =IF($A43="","",COUNTIF('Knowledge test'!$B:$B,$A43)) | C43: =IF($A43="","",COUNTIF('Application test'!$B:$B,$A43)) | D43: =IF($A43="","",COUNTIF(Exhibits!$B:$B,$A43)) | E43: =IF($A43="","",COUNTIF('Reading list'!$B:$B,$A43))
...

Sheet Course info
A1: Course info
A2: Information shown to learners on course cards and the course page. Every text field is required in English and Chinese. The course set-up (languages, study mode, number of lessons) is on the Checklist.
A3: Field | B3: English | C3: Chinese (中文) | D3: Notes
A4: Category | B4: Science | D4: Choose from the list.
A5: Course title | B5: Modeling life | D5: Recommended length: 30 characters (EN) / 14 (中文).
A6: Short description | B6: See how mathematics models life, from population growth to neural activity and disease. Simulate real biological systems with Euler’s method, no prior background in differential equations required. | D6: Recommended length: 225 (EN) / 100 (中文).
A7: Overview | B7: Centred on dynamical systems and feedback, it shows how differential equations underpin homeostasis, population dynamics, neural activity and disease — the very competencies flagged as essential by HHMI/AAMC, and the NSF/AAAS Vision and Change initiative. Rather than mastering by-hand calculus techniques, students learn to simulate systems computationally using Euler's method, requiring no prior background in differential equations. Real examples from physiology, ecology, neuroscience and immunology anchor every concept, starting from day one with a predator–prey ecosystem. The result is a practical, intuitive fluency in dynamical thinking that prepares students for further study and research across the life sciences. | D7: Recommended length: 650 (EN) / 380 (中文).
A9: What you'll learn
A10: At least 4, 6 recommended. One item per row; add rows if needed.
A11: # | B11: English | C11: Chinese (中文) | D11: Notes
A12: 1 | B12: Model biological systems mathematically
A13: 2 | B13: Learn the basics of a programming language
A14: 3 | B14: Explore dynamics across disciplines
A15: 4 | B15: Simulate nonlinear dynamics with Euler's method
A16: 5 | B16: Understand positive and negative feedback
A17: 6 | B17: Build the competencies future physicians and researchers
A19: This course provides
A20: 4 to 6 items, 6 recommended. Choose a preset (its icon and wording are fixed) or "Custom item" and write your own text.
A21: # | B21: Item | C21: Custom text – English | D21: Custom text – Chinese (中文)
A22: 1 | B22: Video & text dual-mode learning
A23: 2 | B23: Multiple reference exhibits
A24: 3 | B24: AI-powered learning assistant
A25: 4 | B25: AI-guided deep comprehension
A26: 5 | B26: Extended readings for context
A27: 6 | B27: Bilingual: 中文 / English

Sheet Lessons
A1: Lessons
A2: One block per lesson – copy a block for each further lesson. Text-mode learning points are taken from the Heading 1 titles in the lesson text; list them here for reference. Learning point titles are always needed in English and Chinese. Start times (mm:ss) are only needed for the video languages the course has.
A4: Lesson | B4: Lesson 1
A5: Lesson ID | B5: L001
A6: Lesson title (EN) | B6: State Spaces, Vector Spaces and Trajectories
A7: Lesson title (中文)
A8: Lesson description (EN) | B8: A system can be thought of as a collection of states at different times.
A9: Lesson description (中文)
A10: # | B10: Text mode title – EN | C10: Text mode title – 中文 | D10: Video mode title – EN | E10: Video mode title – 中文 | F10: Start · EN video | G10: Start · 中文 video
A11: 1.1 | B11: State Variables and State Spaces | D11: State Variables and State Spaces | F11: 00:10
A12: 1.2 | B12: Defining Vectors | D12: Defining Vectors | F12: 06:52
A13: 1.3 | B13: State Space Rules for Operating with Vectors | D13: State Space Rules for Operating with Vectors | F13: 0.40763889
A14: 1.4 | B14: Vectors And Vector Spaces | D14: Vectors And Vector Spaces | F14: 0.7125
A15: 1.5 | B15: Vectors and Trajectories Change in State Space, Time Series Translation | D15: Vectors and Trajectories Change in State Space, Time Series Translation | F15: 0.81597222
A17: Lesson | B17: Lesson 2
A18: Lesson ID | B18: L002
A19: Lesson title (EN) | B19: Pitchfork Bifurcation
A20: Lesson title (中文)
A21: Lesson description (EN) | B21: A new model and a new kind of bifurcation.
A22: Lesson description (中文)
A23: # | B23: Text mode title – EN | C23: Text mode title – 中文 | D23: Video mode title – EN | E23: Video mode title – 中文 | F23: Start · EN video | G23: Start · 中文 video
A24: 2.1 | B24: Pitchfork Bifurcation in a Model of Public Opinion | D24: Pitchfork Bifurcation in a Model of Public Opinion | F24: 0.0069444444
A25: 2.2 | B25: Transcritical Bifurcation | D25: Transcritical Bifurcation | F25: 0.83611111

Sheet Knowledge test
A1: Knowledge test
A2: One question per row, in the order learners will see them. English and Chinese are both required.
A3: Lesson ID | B3: Lesson | C3: Order | D3: Question (EN) | E3: Reference answer (EN) | F3: Question (中文) | G3: Reference answer (中文)
A4: L001 | B4: Lesson 1 | C4: 1 | D4: What is the conceptual model of how science approaches the study of any dynamic system? | E4: It is the mathematical framework of state spaces, vector spaces and trajectories.
A5: L001 | B5: Lesson 1 | C5: 2 | D5: What is a state? | E5: A state is the aspect of a phenomenon that we are investigating. For example, suppose the phenomenon we are interested in is a cup of coffee, then the state might be its location in the room, the amount of coffee in the cup or the temperature of the coffee.
A6: L001 | B6: Lesson 1 | C6: 3 | D6: What determines the choice of state? | E6: That is determined by what change we are interested in understanding. If we are interested in how fast the coffee is evaporating, then we might focus on the volume or weight of coffee in the cup over time rather than where the cup is in the room or the temperature of the coffee in the cup.
A7: L001 | B7: Lesson 1 | C7: 4 | D7: Why do states always have numbers and units attached? | E7: If we are going to use mathematics to describe a system, then the states need to be quantified in terms of a recognised measurement unit. So for example, the weight might be measured in grams or the temperature in degrees Kelvin.
A8: L001 | B8: Lesson 1 | C8: 5 | D8: Does this same modelling approach apply only to the phenomena studied by physics or chemistry? | E8: It also applies outside the material sciences, for example in areas studied by economics or biology. It can be used to model an animal population over time and in this case the state will be the size of the population, i.e. the number of animals in the population.
A9: L001 | B9: Lesson 1 | C9: 6 | D9: What’s a state variable? | E9: A variable is the measured value of the state of a system. For example, temperature is often recorded in degrees Kelvin.
A10: L001 | B10: Lesson 1 | C10: 7 | D10: What is a state space? | E10: A state space is all the possible states a system can be in over time.
A11: L001 | B11: Lesson 1 | C11: 8 | D11: What sort of system is described by more than one state variable? | E11: Sometimes a system’s changes depend on the interaction of different factors, so it takes more than one variable to describe it. Take the example of an animal population where there is a predator-prey relationship, such as sharks and tuna. The shark-tuna population is described by two variables, the number of sharks and the number of tuna at any one time.
A12: L001 | B12: Lesson 1 | C12: 9 | D12: Is the shark-tuna space something different from the ocean, where sharks and tuna live? | E12: Yes, they are very different. For one thing, shark-tuna space is two-dimensional, and real life is three-dimensional. But more importantly, shark-tuna space is populated not by real sharks and real tuna, but by numbers, representing the size of the shark and tuna populations at some time.
A13: L001 | B13: Lesson 1 | C13: 10 | D13: Can state spaces be more than three- dimensional? | E13: Yes, they can. For example, the model of a neuron typically has four variables in its description.
A14: L001 | B14: Lesson 1 | C14: 11 | D14: What is a vector? | E14: A vector is a way of describing a location in state space in relation to the point of origin in the state space. A vector therefore has two attributes: magnitude and direction.
A15: L001 | B15: Lesson 1 | C15: 12 | D15: How do we manipulate vectors mathematically? | E15: There are two ways of doing this: addition and multiplication.
... A29: L002 | B29: Lesson 2 | C29: 8 | D29: Why are bifurcations important in understanding dynamic systems? | E29: Bifurcations help us understand how small changes in a system's parameters can produce qualitative changes in its behaviour, such as changes in the number or stability of equilibria. They are useful for studying phenomena in biology, physics, economics and social systems.

Sheet Application test
A1: Application test
A2: One question per lesson. Reference answers are shown to learners after AI evaluation and are used by the AI as a reference. English and Chinese are both required.
A3: Lesson ID | B3: Lesson | C3: Question (EN) | D3: Reference answer (EN) | E3: Question (中文) | F3: Reference answer (中文)
A4: L001 | B4: Lesson 1 | C4: Suppose an animal population has two genotypes: black hawks and white doves. They continually compete for the same food source. Hawks always fight when they meet other birds. Doves never fight. They either let hawks eat all the food or share the food with another dove. If a hawk competes with another hawk for food, its survival rate decreases by a factor of 3 when it fights and loses and increases by 2 if it wins. It has a 50% chance of winning. If it competes with a dove, it always increases its survival rate by 2 , since the dove doesn’t fight. A dove’s survival rate is unchanged if it meets a hawk. If it meets another dove, the food would increase its survival rate by the same value of 2, but it shares the food equally with the other dove. What mixed population of hawks and doves will be a stable equilibrium? | D4: Mathematically, this sounds like a problem to find the equilibrium points of a differential equation with two variables. And specifically in biology this seems like a straightforward ecological system without any constraints on upper or lower limits where two genotypes interact. That calls for a game theoretic approach and the place to start is the payoff matrix for the hawk and dove encounters. Let’s start with the Hawks. When a Hawk meets a Hawk, then 50% of the time the first hawk wins (+2), and 50% of the time it loses (-3). So expected payoff = (0.5 * 2) + (0.5*-3) = -0.5. If a Hawk meets a Dove, then that’s always +2, so payoff is +2. If a Dove meets a Hawk, it never competes for food, so there is no impact on survival, and payoff is 0. If a Dove meets another Dove, then the food (+2) is shared, so payoff is (0.5 * 2) = 1. This gives the following payoff matrix: Hawk Dove Hawk -0.5 2 Dove 0 1 Now for the differential equation that describes how the composition of a two genotype population changes depending on the fitness of the population genotypes: dX/dT = ( f(a) – f(b))*X*(1-X). This is the replicator formula. In other words, the change in one genotypes’s proportion of a population over time (dX/dT) is calculated using two functions: the difference between that genotype’s fitness and the other genotype’s fitness (f (a) – f(b)) and the frequency with which that genotype competes with the other genotype, calculated as the product of their respective proportions of the total population. If one genotype’s proportion of the population is ¼, then the other genotype’s proportion is 1 – ¼, i.e. ¾. An equilibrium point is reached when dX/dT = 0. Mathematically, an equilibrium is reached when the population is all Hawks or all Doves, i.e. if X means the Hawk proportion of the population, when 1 – X = 0 or X= 0. But the question asks us to find an equilibrium that is a mixed population of Hawks and Doves. To find that equilibrium, we need to expand the expression (f(a) – f(b)) and solve for where (f(a) – f(b)) = 0. We can expand this expression by going back to the payoff matrix and adding in frequency information. Assume again that X is the proportion of Hawks in a population. Then the Hawk’s fitness will be: (-0.5 (payoff or fitness) * X (proportion of Hawks and frequency of meeting a Hawk) + (2 (payoff or fitness) * (1 – X) (proportion of Doves and frequency of meeting a Dove) = -0.5X + 2(1 – X) = 2 – 2.5X Similarly for Doves: ( 0 (payoff or fitness) * X (proportion of Hawks and frequency of meeting a Hawk) + (1 (payoff or fitness) * (1 – X) (proportion of Doves and frequency of meeting a Dove) = 0 + ( 1 – X) = 1 – X. So the mixed equilibrium point will be where: 2 – 2.5 X = 1 – X 1 – 1.5X = 0 2/3 = X. So the Hawk population, as the fitter genotype, is ⅔ of the population and the Doves are therefore ⅓.
A5: L002 | B5: Lesson 2 | C5: Suppose a small community is discussing a proposal to build a new public park. Initially, most residents have neutral opinions. Some support the proposal, while others oppose it, but the community generally remains balanced. As public discussions become more frequent, residents are increasingly influenced by the views of their neighbours. Eventually, two distinct groups emerge: one strongly supports the park, while the other strongly opposes it. The previously neutral position becomes less stable. Question: How can a pitchfork bifurcation explain this change in public opinion? What happens to the stability of the neutral position as social influence increases? | D5: This situation can be explained using a supercritical pitchfork bifurcation. Step 1: Identify the initial equilibrium Initially, the community has a stable neutral position. Small changes in individual opinions do not significantly affect the overall balance, and public opinion tends to return towards neutrality. Step 2: Identify the changing parameter The strength of social influence acts as the bifurcation parameter. As residents interact more frequently and become more influenced by their neighbours, this parameter increases. Step 3: Explain the bifurcation When social influence reaches a critical level, the neutral equilibrium loses stability. Two new stable equilibria emerge, representing strong support for and strong opposition to the proposal. Step 4: Interpret the outcome The community's overall opinion may move towards either of the two stable positions. Small differences in initial opinions or external influences may determine which position becomes dominant. Conclusion A pitchfork bifurcation demonstrates how a gradual increase in social influence can transform a stable, balanced public opinion into two alternative stable states. This illustrates how a relatively small change in a system's conditions can produce a significant change in its behaviour.

Sheet Reading list
A1: Reading list
A2: Recommended reading per lesson, in English only. Type: Book, Article, Paper or Other.
A3: Lesson ID | B3: Lesson | C3: Type | D3: Title | E3: Author | F3: Why we recommend it
A4: L001 | B4: Lesson 1 | C4: Book | D4: Modeling Life, pp 16–23 | E4: Garfinkel, Shevtsov, Guo | F4: A readable introduction to state spaces.
A5: L001 | B5: Lesson 1 | C5: Other | D5: Feeedback and Control Systems, State Space: Linear Systems, lectures 9-13. | E5: MIT Open Courseware | F5: A readable introduction to state spaces.
A6: L001 | B6: Lesson 1 | C6: Article | D6: State Space Representation. | E6: Wikipedia | F6: A readable introduction to state spaces.
A7: L002 | B7: Lesson 2 | C7: Book | D7: Modeling Life, pp 16–23 | E7: Garfinkel, Shevtsov, Guo | F7: A readable introduction to state spaces.
A8: L002 | B8: Lesson 2 | C8: Other | D8: Feeedback and Control Systems, State Space: Linear Systems, lectures 9-13. | E8: MIT Open Courseware | F8: A readable introduction to state spaces.
A9: L002 | B9: Lesson 2 | C9: Article | D9: State Space Representation. | E9: Wikipedia | F9: A readable introduction to state spaces.

Sheet Exhibits
A1: Exhibits
A2: One exhibit per row; the files go in the shared folder. Trigger times are when the exhibit appears in each video (mm:ss); separate several times with commas. In text files, mark the position with [Exhibit: E01].
A3: Lesson ID | B3: Lesson | C3: Exhibit ID | D3: Media type | E3: Title (EN) | F3: Title (中文) | G3: Description (EN) | H3: Description (中文) | I3: Source (EN) | J3: Source (中文) | K3: Trigger · EN video | L3: Trigger · 中文 video
A4: L001 | B4: Lesson 1 | C4: E01 | D4: Image | E4: T, W, V, C | G4: A cup of coffee described by four state variables (T, W, V, C)… | I4: - | K4: 00:37
A5: L001 | B5: Lesson 1 | C5: E01 | D5: Image | E5: Three examples of one-dimensional state spaces | G5: Three examples of one-dimensional state spaces: voltage, population size, and the fraction of a wolf population that has black fur | I5: - | K5: 0.11111111
A6: L002 | B6: Lesson 2 | C6: E03 | D6: Image | E6: T, W, V, C | G6: A cup of coffee described by four state variables (T, W, V, C)… | I6: - | K6: 00:37
A7: L002 | B7: Lesson 2 | C7: E04 | D7: Image | E7: Three examples of one-dimensional state spaces | G7: Three examples of one-dimensional state spaces: voltage, population size, and the fraction of a wolf population that has black fur | I7: - | K7: 0.11111111

Sheet Lists
A1: Status | B1: Applies | C1: Category | D1: LearnLang | E1: StudyMode | F1: Lang | G1: Media | H1: ReadType | I1: YesNo | J1: Provides
A2: Not started | B2: Yes | C2: Science | D2: English & Chinese | E2: Video | F2: EN | G2: Image | H2: Book | I2: Yes | J2: Video & text dual-mode learning
A3: In progress | B3: N/A | C3: Chinese Humanities | D3: English | E3: Text | F3: ZH | G3: Video | H3: Article | I3: No | J3: Multiple reference exhibits
A4: Ready | C4: European Humanities | D4: Chinese | E4: Both | G4: 3D | H4: Paper | J4: AI-powered learning assistant
A5: Needs changes | H5: Other | J5: AI-guided deep comprehension
J6: Extended readings for context
J7: Bilingual: 中文 / English
J8: Custom item
